Using pretrained: False
number of unique_entities -> 1685
number of unique_entities -> 1539
number of unique_entities -> 1598
Training size 2 Val size 2 Test size 2
Initialised relations and entities randomly
Graph created
length of graph keys is  1685
time taken  75.49030780792236
length of neighbors dict is  1685
Total triples count 192259, training triples 134598, validation_triples 19228, test_triples 38433
Opening node_neighbors pickle object
Initial entity dimensions torch.Size([1710, 50]) , relation dimensions torch.Size([86, 50])
Defining model

Model type -> GAT layer with 2 heads used , Initital Embeddings training
length of unique_entities  1685
Number of epochs 800

epoch->  0
Forward pass torch.Size([1710, 200]) torch.Size([86, 200])
Iteration-> 0  , Iteration_time-> 9.3703 , Iteration_loss 4.9133
Forward pass torch.Size([1710, 200]) torch.Size([86, 200])
Iteration-> 1  , Iteration_time-> 4.3758 , Iteration_loss 4.7894
Epoch 0 , average loss 4.851376533508301 , epoch_time 13.748847246170044
Saving Model
Done saving Model

epoch->  1
Forward pass torch.Size([1710, 200]) torch.Size([86, 200])
Traceback (most recent call last):
  File "main.py", line 407, in <module>
    train_gat(args)
  File "main.py", line 263, in train_gat
    loss.backward()
  File "/scratch/bz1030/anaconda3/envs/capstone/lib/python3.7/site-packages/torch/tensor.py", line 166, in backward
    torch.autograd.backward(self, gradient, retain_graph, create_graph)
  File "/scratch/bz1030/anaconda3/envs/capstone/lib/python3.7/site-packages/torch/autograd/__init__.py", line 99, in backward
    allow_unreachable=True)  # allow_unreachable flag
RuntimeError: CUDA out of memory. Tried to allocate 4.79 GiB (GPU 0; 22.38 GiB total capacity; 10.63 GiB already allocated; 3.02 GiB free; 8.20 GiB cached)
